Workbook
Name Addr1: " 4,, 34TH RD., Industrial Park"
Name Addr2: "Taichung, Taiwan, R.O.C"
Name Addr3: "Tel: +886-4-350-1551 Fax: +886-4-350-1252"
Name Addr4: ""
Name Agent: ""
Name AgentTitle: ""
Name Attach: ""
Name BillTo1: "BLK 105, BOON KENG ROAD"
Name BillTo2: "#6-10, KALLANG BASIN"
Name BillTo3: "INDUSTRIAL ESTATE, SINGAPORE 339776 "
Name BillTo4: "Tel: 65-298-8823 Fax: 65-298-8836"
Name c_fax: 21
Name c_pkg: 12
Name CapCtn1: ""
Name CapCtn2: ""
Name CapSum1: "SAY TOTAL USD DOLLAR FIFTEEN THOUSAND SIXTY NINE AND CENTS NINETY ONLY"
Name CapSum2: ""
Name CMSum: 0
Name Company: "SYRIS International Corp."
Name Consignee: "SYRIS"
Name CtnNo: 2996
Name CtnNoTxt: "C/No: 1-2996"
Name Currency: "USD 1:33"
Name CurrencyName: "USD"
Name CurrencyText: "幣別匯率："
Name Cust1: " "
Name Cust2: " "
Name CustName1: "自訂欄１:"
Name CustName2: "自訂欄２:"
Name CustomNo: ""
Name Date: "April 30, 1999"
Name DisPort: " "
Name ETA: ""
Name ETD: ""
Name GWSum: 0
Name Insurance: " "
Name LoadPort: " "
Name MadeIn: "Made in "
Name Memo: " "
Name MyFax: "+886-4-350-1252"
Name MyTel: "+886-4-350-1551"
Name No: "SS880430002"
Name NWSum: 0
Name OLE_LINK6: 運送第1筆!$A$5
Name OrgNo: " "
Name Paid: 0
Name Payment: " "
Name PgNo: 3
Name QtySum: 2996
Name QtyUnit: "PCS"
Name r_b: 21
Name r_e: 39
Name r_rmk1: 18
Name r_rmk2: 54
Name ShipTo1: "BLK 105, BOON KENGROAD"
Name ShipTo2: "#6-10, KALLANG BASIN "
Name ShipTo3: "INDUSTRIAL ESTATE, "
Name ShipTo4: "SINGAPORE 339776 "
Name ShipVia: " "
Name Subject: ""

Sheet 建船資料檔
A6: 船名 | B6: 輯薪輪
A7: 航次 | B7: 260727
A8: 船舶呼號 | B8: BP3379
A9: 船長姓名 | B9: 姜大炎
A10: 船隻掛號 | B10: 15PAHD
A11: 總/淨噸數 | B11: 1486/445
A12: 時間 | B12: 115/7/27
A13: 申請日期 | B13: 115/7/27

Sheet 進口艙單印1份
A1: 中華民國海關艙單 | D1: 船名 | F1: 航次 | H1: 船舶呼號 | J1: 船長姓名 | L1: 船隻掛號
D2: Name of Vessel | F2: VOY NO | H2: Signal letters | J2: Name of MASTER | L2: VESSEL SAG MG
D3: =建船資料檔!B6 -> 輯薪輪 | F3: =建船資料檔!B7 -> 260727 | H3: =建船資料檔!B8 -> BP3379 | J3: =建船資料檔!B9 -> 姜大炎 | L3: =建船資料檔!B10 -> 15PAHD
D4: 船舶國籍 | F4: 總/淨噸數 | H4: 停泊港口及碼頭 | J4: 預定到港時間 | L4: 繫泊時間
A5: 進口 出口 出港 | D5: Nationality | F5: G.R.T./N.R.T | H5: Destination | J5: Time of Arrival | L5: time a Mooring Yeat
A6: INPORT EXPORT TEKOUCK | D6: 中華民國 | F6: =建船資料檔!B11 -> 1486/445 | H6: 料羅港KNH0010W | J6: =建船資料檔!B12 -> 115/7/27 | L6: =J6 -> 115/7/27
A7: 運送人或代理人名稱及代碼 | D7: 到港前一港 | F7: 前一港離港日期 | H7: 報關日期 | J7: 航行次一港 | L7: 受理艙單機關/ | N7: 受理艙單
A8: CAEEIER OR ETS AGENT & CODE | D8: Last port of call | F8: Last port Month Date Hour | J8: Next port of call | L8: 艙單收單機關 | N8: 時間
A9: 新銳船務代理有限公司 代碼1312450 | D9: 廈門 | L9: BG
A10: 主提單號碼或託運單主號 | B10: 艙單號碼/ | C10: 貨物件數及單位(包 | E10: 標記及貨物唯一追蹤號碼 | F10: 貨名、稅則前六碼、危險貨物代碼 | H10: 卸存地點代碼(R)、暫存 | I10: 毛重、體積、 | K10: 收貨人、受通知人、發貨人名稱及地址 | N10: 備註
A11: MASTER DELIVERY ORDER NUMBER/ | B11: 艙單類別 | C11: 裝說明)、合成註記 | E11: SHIPPING MARKS & UNIQUE | F11: BREIF DESCRIPTION OF CARGO, FIRST SIXCODE (SUB-HEADING) OF C.C.C.CODE, | H11: 地點代碼(T)、裝貨港代 | I11: 體積單位 | K11: CONSIGNEE/CONSIGNOR, NOTIFY PARTY NAME & | N11: REMARKS
A12: MASTER BILL OF LADING NUMBER | B12: MANIFEST | C12: TOTAL NUMBER OF | E12: CONSIGNMENT REFERENCE NO. | F12: DANGEROUS GOODS, CODED | H12: 碼(L)、目的地代碼(D) | I12: GROSS WEIGHT | K12: ADDRESS | N12: (含分批、離
A13: /分艙單承攬運送業代碼 | B13: SERIAL NO./ | C13: PACKAGE & PACKAGE | F13: 貨櫃號碼、實櫃種類、貨櫃裝運方式、封條號碼 | H13: 、停泊碼頭(含浮筒)代 | I13: MEASUREMENT | N13: 境海關辦公
A14: DECONSOLIDATOR, CODE/HOUSE | B14: MANIFEST | C14: UNIT(TYPE OF PACKAGE | F14: FULL CONTAINER NO.& TYPE, TRANSPORT | H14: 碼(W) | I14: UNIT | N14: 室代碼、貨
A15: DELIVERY ORDER | B15: CATEGORIES | C15: CO-PACKAGE NOTE | F15: SERVICE REQ., SEAL NUMBER | N15: 物處理指示說明) | R15: 統編
A16: IPC260727702EX | B16: 5501 | C16: 1599 | D16: PKG | E16: TCNU9125529 | F16: =T16&" "&E16&"/"&U16&"/"&V16&"/"&P16 -> EXPRESS PACKAGE TCNU9125529/45G1/2/200405 | H16: R:KHH0638S T:KNH0010W L:CNXMN | I16: 7137 | J16: KGS | K16: 收貨人:JET-F WORLDWIDE EXPRESS CO., LTD. 9F.-1, No. 268, Sec. 2, Fuxing S. Rd., Da’an Dist., Taipei City 10663, Taiwan (R.O.C.) | N16: (1) | O16: JET-F WORLDWIDE EXPRESS CO., LTD. | P16: 200405 | Q16: SAME AS CONSIGNEE | R16: 24951752 | S16: 捷豐 | T16: EXPRESS PACKAGE | U16: 45G1 | V16: 2
A17: 合計 | C17: =SUM(C16:C16) -> 1599 | D17: PKG | I17: =SUM(I16:J16) -> 7137
A18: 船長簽單:
A19: NASTER SIGNATURE | H19: CARRIER OR ITS AGENT SIGNATURE

Sheet T1快遞貨物訊息
A1: T1快遞貨物訊息
A2: 艙號 | B2: 主號 B/L NO. | C2: 分號 | D2: 貨櫃號碼 | E2: 海關封條號碼 | F2: 收貨人 (中/英文公司名稱) | G2: 統編 | H2: 聯繫人 | I2: 卸存地代碼
A3: =進口艙單印1份!B16 -> 5501 | B3: =進口艙單印1份!A16 -> IPC260727702EX | D3: =進口艙單印1份!E16 -> TCNU9125529 | E3: ='貨櫃清單-1份'!J9 -> ESN888 | F3: 捷豐國際物流股份有限公司 JET-F WORLDWIDE EXPRESS CO., LTD. | G3: 24951752 | H3: 2 25148667 WU,JIA-HUA | I3: KHH0638S | J3: =IF(進口艙單印1份!U16="45G1","40HQ","") -> 40HQ | K3: =進口艙單印1份!P16 -> 200405 | L3: =進口艙單印1份!I16 -> 7137

Sheet 准單(紅紙)-2份
C1: 特 別 准 單
A3: 簡5160 | H3: 准單編號:料 | I3: 115
A4: 申請人名稱 | C4: 新銳船務代理有限公司 | G4: 1312450 | H4: 申請日期 | I4: =建船資料檔!B13 -> 115/7/27
A6: 船名或航機班次 | C6: 大佑輪 | E6: 船隻掛號 | G6: =進口艙單印1份!L3 -> 15PAHD | H6: 受理關別 | I6: BG
A10: 卸 存 地 點 | C10: KHH0638S | E10: 進 | G10: =I4 -> 115/7/27 | H10: 停泊碼頭 | I10: 料羅
E11: 口日期
E13: 出
A14: 申請事項 | B14: 下列 | C14: 1.貨物 | E14: 准在關員監視下(註) | G14: 1.將貨櫃卸存本站或內陸集散站（進口報關放行）。
C15: 2.實貨櫃 | G15: 2.將非櫃裝貨物押運或監視進倉存放。
C16: 3.空貨櫃 | G16: 3.船邊免驗提貨（櫃）。4.船邊驗放。
C17: 4.------- | G17: 5.將轉口貨櫃或空櫃卸運入站.6.公證。7重新包裝。
C18: ------ | G18: 8.換櫃.9.轉運他關區貨櫃。
G19: 10.其他:轉運至高雄港(KHH0638S )
A20: 艙單號碼 | C20: 貨物名稱 | F20: 件數/單位 | H20: 毛重(公斤) | I20: 備註
A21: 裝貨單號碼
A22: =進口艙單印1份!B16 -> 5501 | C22: =進口艙單印1份!T16 -> EXPRESS PACKAGE | F22: =進口艙單印1份!C16&進口艙單印1份!D16 -> 1599PKG | H22: =進口艙單印1份!I16 -> 7137 | I22: =進口艙單印1份!E16 -> TCNU9125529
A23: 註:如屬業者自主管理範圍,從其規定辦理. | I23: 海關核准章戳及時間:
A29: 規費證號碼：

Sheet 准單申請-1份 
C1: 特 別 准 單 申 請 表
A3: 簡5159 | H3: ='准單(紅紙)-2份'!H3 -> 准單編號:料 | I3: ='准單(紅紙)-2份'!I3 -> 115
A4: 申請人名稱 | C4: ='准單(紅紙)-2份'!C4:F5 -> 新銳船務代理有限公司 | G4: 1312450 | H4: 申請日期 | I4: ='准單(紅紙)-2份'!I4:J5 -> 115/7/27
A6: 船名或航機班次 | C6: ='准單(紅紙)-2份'!C6:D9 -> 大佑輪 | E6: 船隻掛號 | G6: ='准單(紅紙)-2份'!G6:G9 -> 15PAHD | H6: 受理關別 | I6: BG
A10: 卸 存 地 點 | C10: ='准單(紅紙)-2份'!C10:D13 -> KHH0638S | E10: 進 | G10: =I4 -> 115/7/27 | H10: 停泊碼頭 | I10: 料羅
E11: 口日期
E13: 出
A14: 申請事項 | B14: 下列 | C14: 1.貨物 | E14: 准在關員監視下(註) | G14: ='准單(紅紙)-2份'!G14:I14 -> 1.將貨櫃卸存本站或內陸集散站（進口報關放行）。
C15: 2.實貨櫃 | G15: ='准單(紅紙)-2份'!G15:I15 -> 2.將非櫃裝貨物押運或監視進倉存放。
C16: 3.空貨櫃 | G16: ='准單(紅紙)-2份'!G16:I16 -> 3.船邊免驗提貨（櫃）。4.船邊驗放。
C17: 4.------- | G17: ='准單(紅紙)-2份'!G17:I17 -> 5.將轉口貨櫃或空櫃卸運入站.6.公證。7重新包裝。
C18: ------ | G18: ='准單(紅紙)-2份'!G18:I18 -> 8.換櫃.9.轉運他關區貨櫃。
G19: ='准單(紅紙)-2份'!G19:J19 -> 10.其他:轉運至高雄港(KHH0638S )
A20: 艙單號碼 | C20: 貨物名稱 | F20: 件數/單位 | H20: 毛重(公斤) | I20: 備註
A21: 裝貨單號碼
A22: ='准單(紅紙)-2份'!A22:B22 -> 5501 | C22: ='准單(紅紙)-2份'!C22:E22 -> EXPRESS PACKAGE | F22: ='准單(紅紙)-2份'!F22:H22 -> 1599PKG | H22: ='准單(紅紙)-2份'!H22 -> 7137 | I22: ='准單(紅紙)-2份'!I22 -> TCNU9125529
A23: 上列貨櫃物,請准予依申請事項辦理有關事宜.
B25: 此致 | C25: 財政部關務署高雄關
G27: 申請人及負責人:
A29: 海關處理記錄 | B29: (1) 稽 查 單 位 | D29: (2) 艙 單 單 位 | G29: (3) 分 估 單 位 | H29: (4) 核 發 單 位

Sheet 貨櫃清單-1份
A1: (簡5166) | D1: □ | E1: 1.進口 2.出口 | G1: 貨櫃清單 | I1: NO.
A2: □ | B2: A.實貨櫃 B.空貨櫃
A3: 准單號碼： | E3: 船 名： | G3: =進口艙單印1份!D3 -> 輯薪輪 | H3: 列印時間： | I3: ='准單(紅紙)-2份'!I4 -> 115/7/27
A4: 卸存運往 | B4: 地場站名稱： | C4: KHH0638S 高雄港第一郵聯 | E4: 船隻掛號： | G4: =進口艙單印1份!L3 -> 15PAHD | H4: 列印關員：
A5: 出口裝船地名稱： | C5: 廈門 | E5: 列印階段： | G5: □1.核發准單 2.申請加封 3.裝船結關
A7: 項次 | B7: 貨櫃標記及 | C7: 封條號碼 | D7: 艙單／裝 | E7: 件數／ | G7: 貨櫃運送單 | H7: 貨櫃種類 | I7: 進出站 | J7: 海關處理記錄
B8: 號碼 | D8: 貨單號碼 | E8: 單位 | G8: 號碼 | I8: 註記
A9: 1 | B9: =進口艙單印1份!E16 -> TCNU9125529 | C9: =進口艙單印1份!P16 -> 200405 | D9: =進口艙單印1份!B16 -> 5501 | E9: =進口艙單印1份!C16 -> 1599 | F9: =進口艙單印1份!D16 -> PKG | G9: =B9 -> TCNU9125529 | H9: =進口艙單印1份!U16 -> 45G1 | J9: ESN888
G10: =進口艙單印1份!I16 -> 7137
A11: 倉 儲 業
A12: 船 公 司 簽 章 | G12: 關 員 簽 章
A13: (代理行)
E15: 第 頁

Sheet 運送第1筆
A1: 第一聯：港警聯
D2: 金門料羅 貨櫃(物)運送單(兼出進站通行單)
A3: 2 | B3: 1進口 2 轉運 3轉口 4出口
A4: A | B4: A CY重櫃 B 空櫃 C 非櫃裝 D CFS重櫃
A5: 船名 航次 | B5: ='准單(紅紙)-2份'!C6 -> 大佑輪 | E5: 船隻 掛號 | F5: =進口艙單印1份!L3 -> 15PAHD | G5: S/O艙號 | H5: =進口艙單印1份!B16 -> 5501 | I5: 貨主名稱 | J5: =進口艙單印1份!O16 -> JET-F WORLDWIDE EXPRESS CO., LTD. | M5: 放行總數量 | N5: =進口艙單印1份!C16 -> 1599
A6: 起運站名 | B6: KNH0010W 金門料羅 | C6: 出站時間 | E6: 運往 站名 | F6: ='准單(紅紙)-2份'!C10 -> KHH0638S | G6: 進站時間 | I6: 通關方式 | K6: 放行條件 | M6: 本櫃車數量 | N6: =N5 -> 1599
A7: 貨櫃及加封記錄 | G7: 托運記錄
A8: 貨櫃(物)標記號碼及型態 | D8: 封條號碼 | G8: 車行名稱 | I8: 車號 | K8: 司機姓名 | M8: 駕照號碼
A9: =進口艙單印1份!E16 -> TCNU9125529 | D9: =進口艙單印1份!P16 -> 200405
D10: ='貨櫃清單-1份'!J9 -> ESN888
D11: 船公司 簽 倉儲業 章 | F11: 核准出站提領 關員或自主簽章 | G11: 場站管制員 簽 章 | I11: 落地追蹤 | K11: 出站門哨核章 (關員港警警衛) | M11: 進站門哨核章 (關員港警警衛)
A12: 貨稅 物則 名號 稱別
A13: 本放行單當放行單用時，限____年____月____日當日進站隔日作廢
A14: --------------------------------------撕線------------------------------------------------------------------------------------------------撕線--------------------------------------
A15: 第二聯：海關聯
D16: 金門料羅 貨櫃(物)運送單(兼出進站通行單)
A17: 2 | B17: 1進口 2 轉運 3轉口 4出口
A18: A | B18: A CY重櫃 B 空櫃 C 非櫃裝 D CFS重櫃
A19: 船名航次 | B19: =B5 -> 大佑輪 | E19: 船隻 掛號 | F19: =F5 -> 15PAHD | G19: S/O艙號 | H19: =H5 -> 5501 | I19: 貨主名稱 | J19: =J5 -> JET-F WORLDWIDE EXPRESS CO., LTD. | M19: 放行總數量 | N19: =N5 -> 1599
A20: 起運站名 | B20: =B6 -> KNH0010W 金門料羅 | C20: 出站時間 | E20: 運往 站名 | F20: =F6 -> KHH0638S | G20: 進站時間 | I20: 通關方式 | K20: 放行條件 | M20: 本櫃車數量 | N20: =N6 -> 1599
A21: 貨櫃及加封記錄 | G21: 托運記錄
A22: 貨櫃(物)標記號碼及型態 | D22: 封條號碼 | G22: 車行名稱 | I22: 車號 | K22: 司機姓名 | M22: 駕照號碼
A23: =A9 -> TCNU9125529 | D23: =D9 -> 200405
D24: =D10 -> ESN888
D25: 船公司 簽 倉儲業 章 | F25: 核准出站提領 關員或自主簽章 | G25: 場站管制員 簽 章 | I25: 落地追蹤 | K25: 出站門哨核章 (關員港警警衛) | M25: 進站門哨核章 (關員港警警衛)
A26: 貨稅 物則 名號 稱別
A27: 本放行單當放行單用時，限____年____月____日當日進站隔日作廢
A28: --------------------------------------撕線------------------------------------------------------------------------------------------------撕線--------------------------------------
A29: 第三聯：進站聯
D30: 金門料羅 貨櫃(物)運送單(兼出進站通行單)
A31: 2 | B31: 1進口 2 轉運 3轉口 4出口
A32: A | B32: A CY重櫃 B 空櫃 C 非櫃裝 D CFS重櫃
A33: 船名航次 | B33: =B5 -> 大佑輪 | E33: 船隻 掛號 | F33: =F5 -> 15PAHD | G33: S/O艙號 | H33: =H5 -> 5501 | I33: 貨主名稱 | J33: =J5 -> JET-F WORLDWIDE EXPRESS CO., LTD. | M33: 放行總數量 | N33: =N5 -> 1599
A34: 起運站名 | B34: =B6 -> KNH0010W 金門料羅 | C34: 出站時間 | E34: 運往 站名 | F34: =F6 -> KHH0638S | G34: 進站時間 | I34: 通關方式 | K34: 放行條件 | M34: 本櫃車數量 | N34: =N6 -> 1599
A35: 貨櫃及加封記錄 | G35: 托運記錄
A36: 貨櫃(物)標記號碼及型態 | D36: 封條號碼 | G36: 車行名稱 | I36: 車號 | K36: 司機姓名 | M36: 駕照號碼
A37: =A9 -> TCNU9125529 | D37: =D9 -> 200405
D38: =D10 -> ESN888
D39: 船公司 簽 倉儲業 章 | F39: 核准出站提領 關員或自主簽章 | G39: 場站管制員 簽 章 | I39: 落地追蹤 | K39: 出站門哨核章 (關員港警警衛) | M39: 進站門哨核章 (關員港警警衛)
A40: 貨稅 物則 名號 稱別
...
